<?xml version="1.0" encoding="utf-8"?>
<!-- 四足机器人URDF主文件 | 名称：htdw_4438 | 命名：fl前左/fr前右/rl后左/rr后右 | 肢体：hip髋/thigh大腿/calf小腿/foot脚 | 关节：revolute旋转/fixed固定 -->
<robot name="htdw_4438">
  <!-- 全局复用材质：白色不透明 -->
  <material name="white_material">
    <color rgba="1 1 1 1" />
  </material>

  <!-- 基座连杆：机器人核心躯干 -->
  <link name="base_link">
    <inertial>
      <origin xyz="-0.0014 0.0001 0.0135" rpy="0 0 0" />
      <mass value="2.6821" />
      <inertia ixx="0.0068" ixy="0.0000" ixz="0.0003" iyy="0.0120" iyz="0.0000" izz="0.0122" />
    </inertial>
    <visual>
      <origin xyz="0 0 0" rpy="0 0 0" />
      <geometry>
        <mesh filename="package://quadruped_robot/meshes/base_link.STL" />
      </geometry>
      <material name="white_material" />
    </visual>
    <collision>
      <origin xyz="0 0 0" rpy="0 0 0" />
      <geometry>
        <mesh filename="package://quadruped_robot/meshes/base_link.STL" />
      </geometry>
    </collision>
  </link>

  <!-- 前左腿FL - 髋部：连杆+关节（基座→前左髋） -->
  <link name="fl_hip">
    <inertial>
      <origin xyz="0.0327 0.0044 -0.0001" rpy="0 0 0" />
      <mass value="0.2924" />
      <inertia ixx="0.0001" ixy="0.0000" ixz="0.0000" iyy="0.0004" iyz="0.0000" izz="0.0004" />
    </inertial>
    <visual>
      <origin xyz="0 0 0" rpy="0 0 0" />
      <geometry>
        <mesh filename="package://quadruped_robot/meshes/FL_hip.STL" />
      </geometry>
      <material name="white_material" />
    </visual>
    <collision>
      <origin xyz="0 0 0" rpy="0 0 0" />
      <geometry>
        <mesh filename="package://quadruped_robot/meshes/FL_hip.STL" />
      </geometry>
    </collision>
  </link>
  <joint name="fl_hip_joint" type="revolute">
    <origin xyz="0.0909 0.04 0" rpy="0 0 0" />
    <parent link="base_link" />
    <child link="fl_hip" />
    <axis xyz="-1 0 0" />
    <limit lower="-0.5236" upper="0.5236" effort="2" velocity="4.7124" />
  </joint>

  <!-- 前左腿FL - 大腿：连杆+关节（前左髋→前左大腿） -->
  <link name="fl_thigh">
    <inertial>
      <origin xyz="-0.0014 0.0379 -0.0117" rpy="0 0 0" />
      <mass value="0.4104" />
      <inertia ixx="0.0012" ixy="0.0000" ixz="0.0000" iyy="0.0006" iyz="0.0003" izz="0.0008" />
    </inertial>
    <visual>
      <origin xyz="0 0 0" rpy="0 0 0" />
      <geometry>
        <mesh filename="package://quadruped_robot/meshes/FL_thigh.STL" />
      </geometry>
      <material name="white_material" />
    </visual>
    <collision>
      <origin xyz="0 0 0" rpy="0 0 0" />
      <geometry>
        <mesh filename="package://quadruped_robot/meshes/FL_thigh.STL" />
      </geometry>
    </collision>
  </link>
  <joint name="fl_thigh_joint" type="revolute">
    <origin xyz="0.034 0.0254 0" rpy="0 0 0" />
    <parent link="fl_hip" />
    <child link="fl_thigh" />
    <axis xyz="0 1 0" />
    <limit lower="-0.5236" upper="0.5236" effort="2" velocity="4.7124" />
  </joint>

  <!-- 前左腿FL - 小腿：连杆+关节（前左大腿→前左小腿） -->
  <link name="fl_calf">
    <inertial>
      <origin xyz="0.0108 -0.0001 -0.0529" rpy="0 0 0" />
      <mass value="0.0403" />
      <inertia ixx="0.0002" ixy="0.0000" ixz="0.0000" iyy="0.0002" iyz="0.0000" izz="0.0000" />
    </inertial>
    <visual>
      <origin xyz="0 0 0" rpy="0 0 0" />
      <geometry>
        <mesh filename="package://quadruped_robot/meshes/FL_calf.STL" />
      </geometry>
      <material name="white_material" />
    </visual>
    <collision>
      <origin xyz="0 0 0" rpy="0 0 0" />
      <geometry>
        <mesh filename="package://quadruped_robot/meshes/FL_calf.STL" />
      </geometry>
    </collision>
  </link>
  <joint name="fl_calf_joint" type="revolute">
    <origin xyz="0 0.0604 -0.12" rpy="0 0 0" />
    <parent link="fl_thigh" />
    <child link="fl_calf" />
    <axis xyz="0 1 0" />
    <limit lower="-0.5236" upper="0.5236" effort="2" velocity="4.7124" />
  </joint>

  <!-- 前左腿FL - 脚部：连杆+固定关节（前左小腿→前左脚） -->
  <link name="fl_foot">
    <inertial>
      <origin xyz="0.0038 -0.0007 0.0154" rpy="0 0 0" />
      <mass value="0.0066" />
      <inertia ixx="0.0000" ixy="0.0000" ixz="0.0000" iyy="0.0000" iyz="0.0000" izz="0.0000" />
    </inertial>
    <visual>
      <origin xyz="0 0 0" rpy="0 0 0" />
      <geometry>
        <mesh filename="package://quadruped_robot/meshes/FL_foot.STL" />
      </geometry>
      <material name="white_material" />
    </visual>
    <collision>
      <origin xyz="0 0 0" rpy="0 0 0" />
      <geometry>
        <mesh filename="package://quadruped_robot/meshes/FL_foot.STL" />
      </geometry>
    </collision>
  </link>
  <joint name="fl_foot_joint" type="fixed">
    <origin xyz="0.00206 0.00006 -0.13694" rpy="0 0 0" />
    <parent link="fl_calf" />
    <child link="fl_foot" />
  </joint>

  <!-- 前右腿FR - 髋部：连杆+关节（基座→前右髋） -->
  <link name="fr_hip">
    <inertial>
      <origin xyz="0.0327 -0.0044 0.0001" rpy="0 0 0" />
      <mass value="0.2924" />
      <inertia ixx="0.0001" ixy="0.0000" ixz="0.0000" iyy="0.0004" iyz="0.0000" izz="0.0004" />
    </inertial>
    <visual>
      <origin xyz="0 0 0" rpy="0 0 0" />
      <geometry>
        <mesh filename="package://quadruped_robot/meshes/FR_hip.STL" />
      </geometry>
      <material name="white_material" />
    </visual>
    <collision>
      <origin xyz="0 0 0" rpy="0 0 0" />
      <geometry>
        <mesh filename="package://quadruped_robot/meshes/FR_hip.STL" />
      </geometry>
    </collision>
  </link>
  <joint name="fr_hip_joint" type="revolute">
    <origin xyz="0.0909 -0.04 0" rpy="0 0 0" />
    <parent link="base_link" />
    <child link="fr_hip" />
    <axis xyz="1 0 0" />
    <limit lower="-0.5236" upper="0.5236" effort="2" velocity="4.7124" />
  </joint>

  <!-- 前右腿FR - 大腿：连杆+关节（前右髋→前右大腿） -->
  <link name="fr_thigh">
    <inertial>
      <origin xyz="-0.0013 -0.0379 -0.0116" rpy="0 0 0" />
      <mass value="0.4104" />
      <inertia ixx="0.0012" ixy="0.0000" ixz="0.0000" iyy="0.0006" iyz="-0.0003" izz="0.0008" />
    </inertial>
    <visual>
      <origin xyz="0 0 0" rpy="0 0 0" />
      <geometry>
        <mesh filename="package://quadruped_robot/meshes/FR_thigh.STL" />
      </geometry>
      <material name="white_material" />
    </visual>
    <collision>
      <origin xyz="0 0 0" rpy="0 0 0" />
      <geometry>
        <mesh filename="package://quadruped_robot/meshes/FR_thigh.STL" />
      </geometry>
    </collision>
  </link>
  <joint name="fr_thigh_joint" type="revolute">
    <origin xyz="0.034 -0.0254 0" rpy="0 0 0" />
    <parent link="fr_hip" />
    <child link="fr_thigh" />
    <axis xyz="0 -1 0" />
    <limit lower="-0.5236" upper="0.5236" effort="2" velocity="4.7124" />
  </joint>

  <!-- 前右腿FR - 小腿：连杆+关节（前右大腿→前右小腿） -->
  <link name="fr_calf">
    <inertial>
      <origin xyz="0.0109 0.0001 -0.0530" rpy="0 0 0" />
      <mass value="0.0403" />
      <inertia ixx="0.0002" ixy="0.0000" ixz="0.0000" iyy="0.0002" iyz="0.0000" izz="0.0000" />
    </inertial>
    <visual>
      <origin xyz="0 0 0" rpy="0 0 0" />
      <geometry>
        <mesh filename="package://quadruped_robot/meshes/FR_calf.STL" />
      </geometry>
      <material name="white_material" />
    </visual>
    <collision>
      <origin xyz="0 0 0" rpy="0 0 0" />
      <geometry>
        <mesh filename="package://quadruped_robot/meshes/FR_calf.STL" />
      </geometry>
    </collision>
  </link>
  <joint name="fr_calf_joint" type="revolute">
    <origin xyz="0 -0.0604 -0.12" rpy="0 0 0" />
    <parent link="fr_thigh" />
    <child link="fr_calf" />
    <axis xyz="0 1 0" />
    <limit lower="-0.5236" upper="0.5236" effort="2" velocity="4.7124" />
  </joint>

  <!-- 前右腿FR - 脚部：连杆+固定关节（前右小腿→前右脚） -->
  <link name="fr_foot">
    <inertial>
      <origin xyz="0.0038 -0.0007 0.0154" rpy="0 0 0" />
      <mass value="0.0066" />
      <inertia ixx="0.0000" ixy="0.0000" ixz="0.0000" iyy="0.0000" iyz="0.0000" izz="0.0000" />
    </inertial>
    <visual>
      <origin xyz="0 0 0" rpy="0 0 0" />
      <geometry>
        <mesh filename="package://quadruped_robot/meshes/FR_foot.STL" />
      </geometry>
      <material name="white_material" />
    </visual>
    <collision>
      <origin xyz="0 0 0" rpy="0 0 0" />
      <geometry>
        <mesh filename="package://quadruped_robot/meshes/FR_foot.STL" />
      </geometry>
    </collision>
  </link>
  <joint name="fr_foot_joint" type="fixed">
    <origin xyz="0.00206 0.00006 -0.13694" rpy="0 0 0" />
    <parent link="fr_calf" />
    <child link="fr_foot" />
  </joint>

  <!-- 后左腿RL - 髋部：连杆+关节（基座→后左髋） -->
  <link name="rl_hip">
    <inertial>
      <origin xyz="-0.0327 0.0044 0.0001" rpy="0 0 0" />
      <mass value="0.2924" />
      <inertia ixx="0.0001" ixy="0.0000" ixz="0.0000" iyy="0.0004" iyz="0.0000" izz="0.0004" />
    </inertial>
    <visual>
      <origin xyz="0 0 0" rpy="0 0 0" />
      <geometry>
        <mesh filename="package://quadruped_robot/meshes/RL_hip.STL" />
      </geometry>
      <material name="white_material" />
    </visual>
    <collision>
      <origin xyz="0 0 0" rpy="0 0 0" />
      <geometry>
        <mesh filename="package://quadruped_robot/meshes/RL_hip.STL" />
      </geometry>
    </collision>
  </link>
  <joint name="rl_hip_joint" type="revolute">
    <origin xyz="-0.0909 0.04 0" rpy="0 0 0" />
    <parent link="base_link" />
    <child link="rl_hip" />
    <axis xyz="-1 0 0" />
    <limit lower="-0.5236" upper="0.5236" effort="2" velocity="4.7124" />
  </joint>

  <!-- 后左腿RL - 大腿：连杆+关节（后左髋→后左大腿） -->
  <link name="rl_thigh">
    <inertial>
      <origin xyz="-0.0014 0.0379 -0.0117" rpy="0 0 0" />
      <mass value="0.4104" />
      <inertia ixx="0.0012" ixy="0.0000" ixz="0.0000" iyy="0.0006" iyz="0.0003" izz="0.0008" />
    </inertial>
    <visual>
      <origin xyz="0 0 0" rpy="0 0 0" />
      <geometry>
        <mesh filename="package://quadruped_robot/meshes/RL_thigh.STL" />
      </geometry>
      <material name="white_material" />
    </visual>
    <collision>
      <origin xyz="0 0 0" rpy="0 0 0" />
      <geometry>
        <mesh filename="package://quadruped_robot/meshes/RL_thigh.STL" />
      </geometry>
    </collision>
  </link>
  <joint name="rl_thigh_joint" type="revolute">
    <origin xyz="-0.034 0.0254 0" rpy="0 0 0" />
    <parent link="rl_hip" />
    <child link="rl_thigh" />
    <axis xyz="0 1 0" />
    <limit lower="-0.5236" upper="0.5236" effort="2" velocity="4.7124" />
  </joint>

  <!-- 后左腿RL - 小腿：连杆+关节（后左大腿→后左小腿） -->
  <link name="rl_calf">
    <inertial>
      <origin xyz="0.0108 -0.0001 -0.0529" rpy="0 0 0" />
      <mass value="0.0403" />
      <inertia ixx="0.0002" ixy="0.0000" ixz="0.0000" iyy="0.0002" iyz="0.0000" izz="0.0000" />
    </inertial>
    <visual>
      <origin xyz="0 0 0" rpy="0 0 0" />
      <geometry>
        <mesh filename="package://quadruped_robot/meshes/RL_calf.STL" />
      </geometry>
      <material name="white_material" />
    </visual>
    <collision>
      <origin xyz="0 0 0" rpy="0 0 0" />
      <geometry>
        <mesh filename="package://quadruped_robot/meshes/RL_calf.STL" />
      </geometry>
    </collision>
  </link>
  <joint name="rl_calf_joint" type="revolute">
    <origin xyz="0 0.0604 -0.12" rpy="0 0 0" />
    <parent link="rl_thigh" />
    <child link="rl_calf" />
    <axis xyz="0 1 0" />
    <limit lower="-0.5236" upper="0.5236" effort="2" velocity="4.7124" />
  </joint>

  <!-- 后左腿RL - 脚部：连杆+固定关节（后左小腿→后左脚） -->
  <link name="rl_foot">
    <inertial>
      <origin xyz="0.0038 -0.0007 0.0154" rpy="0 0 0" />
      <mass value="0.0066" />
      <inertia ixx="0.0000" ixy="0.0000" ixz="0.0000" iyy="0.0000" iyz="0.0000" izz="0.0000" />
    </inertial>
    <visual>
      <origin xyz="0 0 0" rpy="0 0 0" />
      <geometry>
        <mesh filename="package://quadruped_robot/meshes/RL_foot.STL" />
      </geometry>
      <material name="white_material" />
    </visual>
    <collision>
      <origin xyz="0 0 0" rpy="0 0 0" />
      <geometry>
        <mesh filename="package://quadruped_robot/meshes/RL_foot.STL" />
      </geometry>
    </collision>
  </link>
  <joint name="rl_foot_joint" type="fixed">
    <origin xyz="-0.00206 0.00006 -0.13694" rpy="0 0 0" />
    <parent link="rl_calf" />
    <child link="rl_foot" />
  </joint>

  <!-- 后右腿RR - 髋部：连杆+关节（基座→后右髋） -->
  <link name="rr_hip">
    <inertial>
      <origin xyz="-0.0327 -0.0044 -0.0001" rpy="0 0 0" />
      <mass value="0.2924" />
      <inertia ixx="0.0001" ixy="0.0000" ixz="0.0000" iyy="0.0004" iyz="0.0000" izz="0.0004" />
    </inertial>
    <visual>
      <origin xyz="0 0 0" rpy="0 0 0" />
      <geometry>
        <mesh filename="package://quadruped_robot/meshes/RR_hip.STL" />
      </geometry>
      <material name="white_material" />
    </visual>
    <collision>
      <origin xyz="0 0 0" rpy="0 0 0" />
      <geometry>
        <mesh filename="package://quadruped_robot/meshes/RR_hip.STL" />
      </geometry>
    </collision>
  </link>
  <joint name="rr_hip_joint" type="revolute">
    <origin xyz="-0.0909 -0.04 0" rpy="0 0 0" />
    <parent link="base_link" />
    <child link="rr_hip" />
    <axis xyz="1 0 0" />
    <limit lower="-0.5236" upper="0.5236" effort="2" velocity="4.7124" />
  </joint>

  <!-- 后右腿RR - 大腿：连杆+关节（后右髋→后右大腿） -->
  <link name="rr_thigh">
    <inertial>
      <origin xyz="-0.0013 -0.0379 -0.0116" rpy="0 0 0" />
      <mass value="0.4104" />
      <inertia ixx="0.0012" ixy="0.0000" ixz="0.0000" iyy="0.0006" iyz="-0.0003" izz="0.0008" />
    </inertial>
    <visual>
      <origin xyz="0 0 0" rpy="0 0 0" />
      <geometry>
        <mesh filename="package://quadruped_robot/meshes/RR_thigh.STL" />
      </geometry>
      <material name="white_material" />
    </visual>
    <collision>
      <origin xyz="0 0 0" rpy="0 0 0" />
      <geometry>
        <mesh filename="package://quadruped_robot/meshes/RR_thigh.STL" />
      </geometry>
    </collision>
  </link>
  <joint name="rr_thigh_joint" type="revolute">
    <origin xyz="-0.034 -0.0254 0" rpy="0 0 0" />
    <parent link="rr_hip" />
    <child link="rr_thigh" />
    <axis xyz="0 -1 0" />
    <limit lower="-0.5236" upper="0.5236" effort="2" velocity="4.7124" />
  </joint>

  <!-- 后右腿RR - 小腿：连杆+关节（后右大腿→后右小腿） -->
  <link name="rr_calf">
    <inertial>
      <origin xyz=" 0.0109 0.0001 -0.0530" rpy="0 0 0" />
      <mass value="0.0403" />
      <inertia ixx="0.0002" ixy="0.0000" ixz="0.0000" iyy="0.0002" iyz="0.0000" izz="0.0000" />
    </inertial>
    <visual>
      <origin xyz="0 0 0" rpy="0 0 0" />
      <geometry>
        <mesh filename="package://quadruped_robot/meshes/RR_calf.STL" />
      </geometry>
      <material name="white_material" />
    </visual>
    <collision>
      <origin xyz="0 0 0" rpy="0 0 0" />
      <geometry>
        <mesh filename="package://quadruped_robot/meshes/RR_calf.STL" />
      </geometry>
    </collision>
  </link>
  <joint name="rr_calf_joint" type="revolute">
    <origin xyz="0 -0.0604 -0.12" rpy="0 0 0" />
    <parent link="rr_thigh" />
    <child link="rr_calf" />
    <axis xyz="0 1 0" />
    <limit lower="-0.5236" upper="0.5236" effort="2" velocity="4.7124" />
  </joint>

  <!-- 后右腿RR - 脚部：连杆+固定关节（后右小腿→后右脚） -->
  <link name="rr_foot">
    <inertial>
      <origin xyz="0.0038 -0.0007 0.0154" rpy="0 0 0" />
      <mass value="0.0066" />
      <inertia ixx="0.0000" ixy="0.0000" ixz="0.0000" iyy="0.0000" iyz="0.0000" izz="0.0000" />
    </inertial>
    <visual>
      <origin xyz="0 0 0" rpy="0 0 0" />
      <geometry>
        <mesh filename="package://quadruped_robot/meshes/RR_foot.STL" />
      </geometry>
      <material name="white_material" />
    </visual>
    <collision>
      <origin xyz="0 0 0" rpy="0 0 0" />
      <geometry>
        <mesh filename="package://quadruped_robot/meshes/RR_foot.STL" />
      </geometry>
    </collision>
  </link>
  <joint name="rr_foot_joint" type="fixed">
    <origin xyz="-0.00206 0.00006 -0.13694" rpy="0 0 0" />
    <parent link="rr_calf" />
    <child link="rr_foot" />
  </joint>

</robot>